<mujoco model="cart pole">
    <compiler inertiafromgeom="true"/>
    
    <option iterations="1" ls_iterations="5">
        <flag eulerdamp="disable"/>
    </option>

    <default>
        <joint armature="0" damping="1"/>
        <geom contype="0" conaffinity="0" friction="1 0.1 0.1"/>
    </default>

    <worldbody>
        <light diffuse=".5 .5 .5" pos="0 0 3" dir="0 0 -1"/>
        <geom name="rail" type="capsule"  size="0.02 1.5" pos="0 0 0" quat="1 0 1 0" rgba="1 1 1 1"/>
        <body name="cart" pos="0 0 0">
            <joint name="slider" type="slide" axis="1 0 0" pos="0 0 0" limited="true" range="-1.5 1.5"/>
            <geom name="cart_geom" pos="0 0 0" quat="1 0 1 0" size="0.1 0.1" type="capsule"/>
            <body name="pole" pos="0 0 0">
                <joint name="hinge" type="hinge" axis="0 1 0" pos="0 0 0"/>
                <geom name="pole_geom" type="capsule" size="0.049 0.3"  fromto="0 0 0 0.001 0 0.6"/>
            </body>
        </body>
    </worldbody>

    <actuator>
        <motor ctrllimited="true" ctrlrange="-3 3" gear="100" joint="slider" name="slide"/>
    </actuator>

</mujoco>