<mujoco model="arm">
    <compiler inertiafromgeom="true"/>

    <default>
        <joint armature="0.001" damping="0.1"/>
        <geom contype="0" conaffinity="0" friction="1 0.1 0.1"/>
    </default>

    <!-- Arm Model: -->
    <worldbody>
        <geom name="base" type="cylinder" size="0.05 0.01" pos="0 0 0" quat="1 0 0 0"/>
        <body name="link_1" pos="0 0 0">
            <joint name="link_1_joint" type="hinge" axis="0 1 0"/>
            <geom name="link_1_geom" type="capsule" size="0.01 0.1" pos="0 0 0.1" quat="1 0 0 0"/>
            <geom name="link_1_joint_geom" type="cylinder" size="0.01 0.01" pos="0 0 0.2" quat="1 1 0 0"/>
            <body name="link_2" pos="0 0 0.2">
                <joint name="link_2_joint" type="hinge" axis="0 1 0"/>
                <geom name="link_2_geom" type="capsule" size="0.01 0.1" pos="0 0 0.1" quat="1 0 0 0"/>
                <site name="end_effector" pos="0 0 0.2" size="0.01" type="sphere" rgba="1 0 0 1"/>
            </body>
        </body> 
    </worldbody>

    <actuator>
        <motor name="link_1_motor" ctrllimited="true" ctrlrange="-3 3" joint="link_1_joint"/>
        <motor name="link_2_motor" ctrllimited="true" ctrlrange="-3 3" joint="link_2_joint"/>
    </actuator>

</mujoco>