<mujoco model="MuJoCo Model">
  <compiler angle="radian"/>
  
  <option iterations="3" ls_iterations="5" timestep=".002" integrator="Euler">
    <flag eulerdamp="disable"/>
  </option>
  
  <default>
  	<geom condim="3" contype="0" conaffinity="0"/>
  </default>
  
  <worldbody>
    <body name="torso" pos="0 0 0.2">
      <joint name="torso_joint" type="free" limited="false" actuatorfrclimited="false"/>
      <site name="torso_site" pos="0 0 0.05" type="sphere" rgba="1 0 0 1"/> 
      <geom size="0.125 0.075 0.05" type="box" mass="10" rgba="0.694118 0.65098 0.533333 1" contype="0" conaffinity="1"/>
      <body name="torso_left_thigh" pos="-0.02 0.075 0">
        <joint name="torso_left_thigh_joint" pos="0 0 0" axis="0 1 0" armature="0.0072" damping="5"/>
        <geom name="torso_left_thigh_geom" size="0.02 0.05" pos="0 0.02 -0.05" type="capsule" mass="0.5" rgba="0.694118 0.65098 0.533333 1"/>
        <site name="tl_thigh_site" pos="0 0 0" rgba="1 0 0 1"/>            
        <body name="torso_left_shin" pos="0 0.06 -0.1">
          <joint name="torso_left_thigh_shin_joint" pos="0 0 0" axis="0 1 0" armature="0.01805" damping="5"/>
          <geom name="torso_left_shin_geom" size="0.02 0.08" quat="0.707107 0 0.707107 0" type="capsule" mass="0.5" rgba="0.694118 0.65098 0.533333 1"/>
          <site name="tl_shin_site" pos="0 0 0" rgba="1 0 0 1"/>            
          <body name="torso_left_front_wheel" pos="0.08 0.055 0">
            <!-- <joint name="torso_left_shin_front_wheel_joint" pos="0 0 0" axis="0 1 0" armature="1e-05" damping="0.2"/> -->
            <geom name="torso_left_front_wheel_geom" size="0.065 0.035" quat="0.707107 0.707107 0 0" type="cylinder" solref="0.2 0.5" mass="0.5" rgba="0.694118 0.65098 0.533333 1" contype="0" conaffinity="1"/>
            <!-- <site name="lf_wheel_site" pos="0 0 0" size="0.08" type="ellipsoid" rgba="1 0 0 1"/>             -->
            <site name="tlf_wheel_site" pos="0 0 0" size="0.065 0.065 0.035" quat="0.707107 0.707107 0 0" type="ellipsoid" rgba="1 0 0 1"/>            
          </body>
          <body name="torso_left_rear_wheel" pos="-0.08 0.055 0">
            <!-- <joint name="torso_left_shin_rear_wheel_joint" pos="0 0 0" axis="0 1 0" armature="1e-05" damping="0.2"/> -->
            <geom name="torso_left_rear_wheel_geom" size="0.065 0.035" quat="0.707107 0.707107 0 0" type="cylinder" solref="0.2 0.5" mass="0.5" rgba="0.694118 0.65098 0.533333 1" contype="0" conaffinity="1"/>
            <site name="tlr_wheel_site" pos="0 0 0" size="0.065 0.065 0.035" quat="0.707107 0.707107 0 0" type="ellipsoid" rgba="1 0 0 1"/>            
          </body>
        </body>
      </body>
      <body name="torso_right_thigh" pos="-0.02 -0.075 0">
        <joint name="torso_right_thigh_joint" pos="0 0 0" axis="0 1 0" armature="0.0072" damping="5"/>
        <geom name="torso_right_thigh_geom" size="0.02 0.05" pos="0 -0.02 -0.05" type="capsule" mass="0.5" rgba="0.694118 0.65098 0.533333 1"/>
        <site name="tr_thigh_site" pos="0 0 0" rgba="1 0 0 1"/>            
        <body name="torso_right_shin" pos="0 -0.06 -0.1">
          <joint name="torso_right_thigh_shin_joint" pos="0 0 0" axis="0 1 0" armature="0.01805" damping="5"/>
          <geom name="torso_right_shin_geom" size="0.02 0.08" quat="0.707107 0 0.707107 0" type="capsule" mass="0.5" rgba="0.694118 0.65098 0.533333 1"/>
          <site name="tr_shin_site" pos="0 0 0" rgba="1 0 0 1"/>            
          <body name="torso_right_front_wheel" pos="0.08 -0.055 0">
            <!-- <joint name="torso_right_shin_front_wheel_joint" pos="0 0 0" axis="0 1 0" armature="1e-05" damping="0.2"/> -->
            <geom name="torso_right_front_wheel_geom" size="0.065 0.035" quat="0.707107 0.707107 0 0" type="cylinder" solref="0.2 0.5" mass="0.5" rgba="0.694118 0.65098 0.533333 1" contype="0" conaffinity="1"/>
            <site name="trf_wheel_site" pos="0 0 0" size="0.065 0.065 0.035" quat="0.707107 0.707107 0 0" type="ellipsoid" rgba="1 0 0 1"/>            
          </body>
          <body name="torso_right_rear_wheel" pos="-0.08 -0.055 0">
            <!-- <joint name="torso_right_shin_rear_wheel_joint" pos="0 0 0" axis="0 1 0" armature="1e-05" damping="0.2"/> -->
            <geom name="torso_right_rear_wheel_geom" size="0.065 0.035" quat="0.707107 0.707107 0 0" type="cylinder" solref="0.2 0.5" mass="0.5" rgba="0.694118 0.65098 0.533333 1" contype="0" conaffinity="1"/>
            <site name="trr_wheel_site" pos="0 0 0" size="0.065 0.065 0.035" quat="0.707107 0.707107 0 0" type="ellipsoid" rgba="1 0 0 1"/>            
          </body>
        </body>
      </body>
      <body name="head" pos="0.3 0 0">
        <!-- <site name="head_site" pos="0 0 0.05" type="sphere" rgba="1 0 0 1"/>             -->
        <!-- <joint name="head_joint" pos="-0.125 0 0" axis="1 0 0" stiffness="10" range="-0.174533 0.174533" damping="1"/> -->
        <geom size="0.125 0.075 0.05" type="box" mass="10" rgba="0.694118 0.65098 0.533333 1" contype="0" conaffinity="1"/>
        <body name="head_left_thigh" pos="0.02 0.075 0">
          <joint name="head_left_thigh_joint" pos="0 0 0" axis="0 1 0" armature="0.0072" damping="5"/>
          <geom name="head_left_thigh_geom" size="0.02 0.05" pos="0 0.02 -0.05" type="capsule" mass="0.5" rgba="0.694118 0.65098 0.533333 1"/>
          <site name="hl_thigh_site" pos="0 0 0" rgba="1 0 0 1"/>            
          <body name="head_left_shin" pos="0 0.06 -0.1">
            <joint name="head_left_thigh_shin_joint" pos="0 0 0" axis="0 1 0" armature="0.01805" damping="5"/>
            <geom name="head_left_shin_geom" size="0.02 0.08" quat="0.707107 0 0.707107 0" type="capsule" mass="0.5" rgba="0.694118 0.65098 0.533333 1"/>
            <site name="hl_shin_site" pos="0 0 0" rgba="1 0 0 1"/>            
            <body name="head_left_front_wheel" pos="0.08 0.055 0">
              <!-- <joint name="head_left_shin_front_wheel_joint" pos="0 0 0" axis="0 1 0" armature="1e-05" damping="0.2"/> -->
              <geom name="head_left_front_wheel_geom" size="0.065 0.035" quat="0.707107 0.707107 0 0" type="cylinder" solref="0.2 0.5" mass="0.5" rgba="0.694118 0.65098 0.533333 1" contype="0" conaffinity="1"/>
              <site name="hlf_wheel_site" pos="0 0 0" size="0.065 0.065 0.035" quat="0.707107 0.707107 0 0" type="ellipsoid" rgba="1 0 0 1"/>            
            </body>
            <body name="head_left_rear_wheel" pos="-0.08 0.055 0">
              <!-- <joint name="head_left_shin_rear_wheel_joint" pos="0 0 0" axis="0 1 0" armature="1e-05" damping="0.2"/> -->
              <geom name="head_left_rear_wheel_geom" size="0.065 0.035" quat="0.707107 0.707107 0 0" type="cylinder" solref="0.2 0.5" mass="0.5" rgba="0.694118 0.65098 0.533333 1" contype="0" conaffinity="1"/>
              <site name="hlr_wheel_site" pos="0 0 0" size="0.065 0.065 0.035" quat="0.707107 0.707107 0 0" type="ellipsoid" rgba="1 0 0 1"/>            
            </body>
          </body>
        </body>
        <body name="head_right_thigh" pos="0.02 -0.075 0">
          <joint name="head_right_thigh_joint" pos="0 0 0" axis="0 1 0" armature="0.0072" damping="5"/>
          <geom name="head_right_thigh_geom" size="0.02 0.05" pos="0 -0.02 -0.05" type="capsule" mass="0.5" rgba="0.694118 0.65098 0.533333 1"/>
          <site name="hr_thigh_site" pos="0 0 0" rgba="1 0 0 1"/>            
          <body name="head_right_shin" pos="0 -0.06 -0.1">
            <joint name="head_right_thigh_shin_joint" pos="0 0 0" axis="0 1 0" armature="0.01805" damping="5"/>
            <geom name="head_right_shin_geom" size="0.02 0.08" quat="0.707107 0 0.707107 0" type="capsule" mass="0.5" rgba="0.694118 0.65098 0.533333 1"/>
            <site name="hr_shin_site" pos="0 0 0" rgba="1 0 0 1"/>            
            <body name="head_right_front_wheel" pos="0.08 -0.055 0">
              <!-- <joint name="head_right_shin_front_wheel_joint" pos="0 0 0" axis="0 1 0" armature="1e-05" damping="0.2"/> -->
              <geom name="head_right_front_wheel_geom" size="0.065 0.035" quat="0.707107 0.707107 0 0" type="cylinder" solref="0.2 0.5" mass="0.5" rgba="0.694118 0.65098 0.533333 1" contype="0" conaffinity="1"/>
              <site name="hrf_wheel_site" pos="0 0 0" size="0.065 0.065 0.035" quat="0.707107 0.707107 0 0" type="ellipsoid" rgba="1 0 0 1"/>            
            </body>
            <body name="head_right_rear_wheel" pos="-0.08 -0.055 0">
              <!-- <joint name="head_right_shin_rear_wheel_joint" pos="0 0 0" axis="0 1 0" armature="1e-05" damping="0.2"/> -->
              <geom name="head_right_rear_wheel_geom" size="0.065 0.035" quat="0.707107 0.707107 0 0" type="cylinder" solref="0.2 0.5" mass="0.5" rgba="0.694118 0.65098 0.533333 1" contype="0" conaffinity="1"/>
              <site name="hrr_wheel_site" pos="0 0 0" size="0.065 0.065 0.035" quat="0.707107 0.707107 0 0" type="ellipsoid" rgba="1 0 0 1"/>            
            </body>
          </body>
        </body>
      </body>
    </body>
  </worldbody>

  <actuator>
    <general name="bl_hip" joint="torso_left_thigh_joint"/>
    <general name="bl_knee" joint="torso_left_thigh_shin_joint"/>
    <!-- <general name="bl_wheel1_joint" joint="torso_left_shin_front_wheel_joint"/> -->
    <!-- <general name="bl_wheel2_joint" joint="torso_left_shin_rear_wheel_joint"/> -->
    <general name="br_hip" joint="torso_right_thigh_joint"/>
    <general name="br_knee" joint="torso_right_thigh_shin_joint"/>
    <!-- <general name="br_wheel1_joint" joint="torso_right_shin_front_wheel_joint"/> -->
    <!-- <general name="br_wheel2_joint" joint="torso_right_shin_rear_wheel_joint"/> -->
    <general name="fl_hip" joint="head_left_thigh_joint"/>
    <general name="fl_knee" joint="head_left_thigh_shin_joint"/>
    <!-- <general name="fl_wheel1_joint" joint="head_left_shin_front_wheel_joint"/> -->
    <!-- <general name="fl_wheel2_joint" joint="head_left_shin_rear_wheel_joint"/> -->
    <general name="fr_hip" joint="head_right_thigh_joint"/>
    <general name="fr_knee" joint="head_right_thigh_shin_joint"/>
    <!-- <general name="fr_wheel1_joint" joint="head_right_shin_front_wheel_joint"/> -->
    <!-- <general name="fr_wheel2_joint" joint="head_right_shin_rear_wheel_joint"/> -->
  </actuator>

    <!-- key frame has 0,0 for wheel sites because the bodies have the positions fixed/initialized -->
    <sensor>
    	<framezaxis objtype="site" objname="torso_site" name="upvector"/>
    	<gyro site="torso_site" name="gyro"/>
    	<velocimeter site="torso_site" name="local_linvel"/>
    </sensor>
    <keyframe>
      <key name="home"       
        qpos="0 0 0.1875 1 0 0 0 
              0 0 
              0 0 
              0 0 
              0 0"
        ctrl="0 0 
              0 0 
              0 0 
              0 0"/>
      <key name="flat"       
        qpos='0 0 0.05 1 0 0 0 1.71253 -1.71287 1.71253 -1.71287 -1.71253 1.71287 -1.71253 1.71287'
        ctrl="0 0 
              0 0 
              0 0 
              0 0"/>
      <key name="flat_up"       
        qpos='0.0898423 -0.0025112 0.05 1 0 0 0 3.14 3.14 3.14 3.14 3.14 3.14 3.14 3.14'
        ctrl="0 0 
              0 0 
              0 0 
              0 0"/>              
    </keyframe>
        <!-- qpos='0.0898423 -0.0025112 0.05 1 0 0 0 3.62333 -5.46591 3.62333 -5.46591 3.62333 -5.46591 3.62333 -5.46591 ' -->

</mujoco>
